[1;32m

 ___             _     _   _ 
|  _|_ _ _ _ ___| |___|_|_| |___ ___ 
|  _| | |_'_| . | | . | | . | -_|  _|
|_| |___|_,_|  _|_|___|_|___|___|_|
            |_|

[1m[42m{version 1.0.0}[m

[m[!] legal disclaimer: Usage of fuxploider for attacking targets without
prior mutual consent is illegal. It is the end user's responsibility to obey
all applicable local, state and federal laws. Developers assume no liability
and are not responsible for any misuse or damage caused by this program.

[*] starting at 10:41:24
Traceback (most recent call last):
  File "/usr/local/lib/python3.12/site-packages/urllib3/connection.py", line 198, in _new_conn
    sock = connection.create_connection(
           ^^^^^^^^^^^^^^^^^^^^^^^^^^^^^
  File "/usr/local/lib/python3.12/site-packages/urllib3/util/connection.py", line 60, in create_connection
    for res in socket.getaddrinfo(host, port, family, socket.SOCK_STREAM):
               ^^^^^^^^^^^^^^^^^^^^^^^^^^^^^^^^^^^^^^^^^^^^^^^^^^^^^^^^^^
  File "/usr/local/lib/python3.12/socket.py", line 963, in getaddrinfo
    for res in _socket.getaddrinfo(host, port, family, type, proto, flags):
               ^^^^^^^^^^^^^^^^^^^^^^^^^^^^^^^^^^^^^^^^^^^^^^^^^^^^^^^^^^^
socket.gaierror: [Errno -2] Name or service not known

The above exception was the direct cause of the following exception:

Traceback (most recent call last):
  File "/usr/local/lib/python3.12/site-packages/urllib3/connectionpool.py", line 793, in urlopen
    response = self._make_request(
               ^^^^^^^^^^^^^^^^^^^
  File "/usr/local/lib/python3.12/site-packages/urllib3/connectionpool.py", line 496, in _make_request
    conn.request(
  File "/usr/local/lib/python3.12/site-packages/urllib3/connection.py", line 400, in request
    self.endheaders()
  File "/usr/local/lib/python3.12/http/client.py", line 1322, in endheaders
    self._send_output(message_body, encode_chunked=encode_chunked)
  File "/usr/local/lib/python3.12/http/client.py", line 1081, in _send_output
    self.send(msg)
  File "/usr/local/lib/python3.12/http/client.py", line 1025, in send
    self.connect()
  File "/usr/local/lib/python3.12/site-packages/urllib3/connection.py", line 238, in connect
    self.sock = self._new_conn()
                ^^^^^^^^^^^^^^^^
  File "/usr/local/lib/python3.12/site-packages/urllib3/connection.py", line 205, in _new_conn
    raise NameResolutionError(self.host, self, e) from e
urllib3.exceptions.NameResolutionError: <urllib3.connection.HTTPConnection object at 0x71c169482150>: Failed to resolve '172.22.1' ([Errno -2] Name or service not known)

The above exception was the direct cause of the following exception:

Traceback (most recent call last):
  File "/usr/local/lib/python3.12/site-packages/requests/adapters.py", line 486, in send
    resp = conn.urlopen(
           ^^^^^^^^^^^^^
  File "/usr/local/lib/python3.12/site-packages/urllib3/connectionpool.py", line 847, in urlopen
    retries = retries.increment(
              ^^^^^^^^^^^^^^^^^^
  File "/usr/local/lib/python3.12/site-packages/urllib3/util/retry.py", line 515, in increment
    raise MaxRetryError(_pool, url, reason) from reason  # type: ignore[arg-type]
    ^^^^^^^^^^^^^^^^^^^^^^^^^^^^^^^^^^^^^^^^^^^^^^^^^^^
urllib3.exceptions.MaxRetryError: HTTPConnectionPool(host='172.22.1.', port=80): Max retries exceeded with url: / (Caused by NameResolutionError("<urllib3.connection.HTTPConnection object at 0x71c169482150>: Failed to resolve '172.22.1' ([Errno -2] Name or service not known)"))

During handling of the above exception, another exception occurred:

Traceback (most recent call last):
  File "/fuxploider/UploadForm.py", line 47, in setup
    initGet = self.session.get(self.formUrl, headers={"Accept-Encoding":None})
              ^^^^^^^^^^^^^^^^^^^^^^^^^^^^^^^^^^^^^^^^^^^^^^^^^^^^^^^^^^^^^^^^
  File "/usr/local/lib/python3.12/site-packages/requests/sessions.py", line 602, in get
    return self.request("GET", url, **kwargs)
           ^^^^^^^^^^^^^^^^^^^^^^^^^^^^^^^^^^
  File "/usr/local/lib/python3.12/site-packages/requests/sessions.py", line 589, in request
    resp = self.send(prep, **send_kwargs)
           ^^^^^^^^^^^^^^^^^^^^^^^^^^^^^^
  File "/usr/local/lib/python3.12/site-packages/requests/sessions.py", line 703, in send
    r = adapter.send(request, **kwargs)
        ^^^^^^^^^^^^^^^^^^^^^^^^^^^^^^^
  File "/usr/local/lib/python3.12/site-packages/requests/adapters.py", line 519, in send
    raise ConnectionError(e, request=request)
requests.exceptions.ConnectionError: HTTPConnectionPool(host='172.22.1.', port=80): Max retries exceeded with url: / (Caused by NameResolutionError("<urllib3.connection.HTTPConnection object at 0x71c169482150>: Failed to resolve '172.22.1' ([Errno -2] Name or service not known)"))

During handling of the above exception, another exception occurred:

Traceback (most recent call last):
  File "/fuxploider/fuxploider.py", line 249, in <module>
    up.setup(args.url)
  File "/fuxploider/UploadForm.py", line 58, in setup
    self.logger.critical("%s: Host unreachable (%s)", getHost(initUrl), e)
                                                      ^^^^^^^^^^^^^^^^
  File "/fuxploider/utils.py", line 80, in getHost
    return str(res.group(2))
               ^^^^^^^^^
AttributeError: 'NoneType' object has no attribute 'group'
